<robot name="my_SCARA">
    <link name="base_link" />

    <link name="stand_link">
        <visual>
            <geometry>
                <cylinder radius="0.2" length="0.2" />
            </geometry>
            <origin xyz="0 0 0" rpy="0 0 0" />
            <material name="red">
                <color rgba="1.0 0 0 1.0" />
            </material>
        </visual>
        <collision>
            <geometry>
                <cylinder radius="0.2" length="0.2" />
            </geometry>
            <origin xyz="0 0 0" rpy="0 0 0" />
        </collision>
        <inertial>
            <origin xyz="0 0 0" rpy="0 0 0" />
            <mass value="10" />
            <inertia ixx="0.1333" ixy="0" ixz="0" iyx="0" iyy="0.1333" iyz="0" izx="0" izy="0" izz="0.2" />
        </inertial>
    </link>

    <link name="arm1_link">
        <visual>
            <geometry>
                <box size="0.6 0.1 0.05 " />
            </geometry>
            <origin xyz="0.25 0 0" rpy="0 0 0" />
            <material name="blue">
                <color rgba="0.0 0.0 1.0 1.0" />
            </material>
        </visual>
        <collision>
            <geometry>
                <box size="0.6 0.1 0.05 " />
            </geometry>
            <origin xyz="0.25 0 0" rpy="0 0 0" />
        </collision>
        <inertial>
            <origin xyz="0.25 0 0" rpy="0 0 0" />
            <mass value="0.6" />
            <inertia ixx="0.000625" ixy="0" ixz="0" iyx="0" iyy="0.0556250" iyz="0" izx="0" izy="0" izz="0.056" />
        </inertial>
    </link>

    <link name="arm2_link">
        <visual>
            <geometry>
                <box size="0.6 0.1 0.05" />
            </geometry>
            <origin xyz="0.25 0 0.025" rpy="0 0 0" />
            <material name="green">
                <color rgba="0.0 1.0 0.0 1.0" />
            </material>
        </visual>
        <collision>
            <geometry>
                <box size="0.6 0.1 0.05" />
            </geometry>
            <origin xyz="0.25 0 0.025" rpy="0 0 0" />
        </collision>
        <inertial>
            <origin xyz="0.25 0 0" rpy="0 0 0" />
            <mass value="0.6" />
            <inertia ixx="0.000625" ixy="0" ixz="0" iyx="0" iyy="0.0556250" iyz="0" izx="0" izy="0" izz="0.056" />
        </inertial>
    </link>

    <joint name="base_stand" type="fixed">
        <parent link="base_link" />
        <child link="stand_link" />
        <origin xyz="0 0 0.1" rpy="0 0 0" />
    </joint>
    <joint name="stand_arm1" type="revolute">
        <parent link="stand_link" />
        <child link="arm1_link" />
        <origin xyz="0 0 0.125" rpy="0 0 0" />
        <limit lower="-2.09439510239" upper="2.09439510239" effort="10" velocity="10" />
        <joint_properties damping="0.0" friction="0.0" />
        <axis xyz="0 0 1" />
    </joint>
    <joint name="arm1_arm2" type="revolute">
        <parent link="arm1_link" />
        <child link="arm2_link" />
        <origin xyz="0.5 0 0.0125" rpy="0 0 0" />
        <limit lower="-2.09439510239" upper="2.09439510239" effort="10" velocity="10" />
        <joint_properties damping="0.0" friction="0.0" />
        <axis xyz="0 0 1" />
    </joint>

    <transmission name ="arm1_trans">
        <type>transmission_interface/SimpleTransmission</type>
        <joint name="stand_arm1">
            <hardwareInterface>hardware_interface/EffortJointInterface</hardwareInterface>
        </joint>
        <actuator name="arm1_motor">
            <hardwareInterface>hardware_interface/EffortJointInterface</hardwareInterface>
            <mechanismReduction>1</mechanismReduction>
        </actuator>
    </transmission>
    <transmission name="arm1_trans">
        <type>transmission_interface/SimpleTransmission</type>
        <joint name="arm1_arm2">
            <hardwareInterface>hardware_interface/EffortJointInterface</hardwareInterface>
        </joint>
        <actuator name="arm1_motor">
            <hardwareInterface>hardware_interface/EffortJointInterface</hardwareInterface>
            <mechanismReduction>1</mechanismReduction>
        </actuator>
    </transmission>

    <gazebo reference = "stand_link">
        <material>Gazebo/Red</material>
    </gazebo>
    <gazebo reference="arm1_link">
        <material>Gazebo/Blue</material>
    </gazebo>
    <gazebo reference="arm2_link">
        <material>Gazebo/Green</material>
    </gazebo>

    <gazebo>
        <plugin name="gazebo_ros_control" filename="libgazebo_ros_control.so">
            <robotNamespace>/my_SCARA</robotNamespace>
            <robotSimType>gazebo_ros_control/DefaultRobotHWSim</robotSimType>
            <legacyModeNS>true</legacyModeNS>
        </plugin>
    </gazebo>
</robot>